2025-05-16 07:58:27,387 INFO sqlalchemy.engine.Engine BEGIN (implicit)
2025-05-16 07:58:27,390 INFO sqlalchemy.engine.Engine SELECT users.id, users.username, users.email, users.hashed_password, users.created_at, users.updated_at 
FROM users 
WHERE users.username = ?
2025-05-16 07:58:27,390 INFO sqlalchemy.engine.Engine [generated in 0.00023s] ('test_user',)
2025-05-16 07:58:27,391 INFO sqlalchemy.engine.Engine ROLLBACK
INFO:     172.31.128.17:40160 - "POST /api/v1/register HTTP/1.1" 500 Internal Server Error
ERROR:    Exception in ASGI application
Traceback (most recent call last):
  File "/home/runner/workspace/.pythonlibs/lib/python3.12/site-packages/sqlalchemy/engine/base.py", line 1963, in _exec_single_context
    self.dialect.do_execute(
  File "/home/runner/workspace/.pythonlibs/lib/python3.12/site-packages/sqlalchemy/engine/default.py", line 943, in do_execute
    cursor.execute(statement, parameters)
  File "/home/runner/workspace/.pythonlibs/lib/python3.12/site-packages/sqlalchemy/dialects/sqlite/aiosqlite.py", line 149, in execute
    self._adapt_connection._handle_exception(error)
  File "/home/runner/workspace/.pythonlibs/lib/python3.12/site-packages/sqlalchemy/dialects/sqlite/aiosqlite.py", line 300, in _handle_exception
    raise error
  File "/home/runner/workspace/.pythonlibs/lib/python3.12/site-packages/sqlalchemy/dialects/sqlite/aiosqlite.py", line 131, in execute
    self.await_(_cursor.execute(operation, parameters))
  File "/home/runner/workspace/.pythonlibs/lib/python3.12/site-packages/sqlalchemy/util/_concurrency_py3k.py", line 132, in await_only
    return current.parent.switch(awaitable)  # type: ignore[no-any-return,attr-defined] # noqa: E501
           ^^^^^^^^^^^^^^^^^^^^^^^^^^^^^^^^
  File "/home/runner/workspace/.pythonlibs/lib/python3.12/site-packages/sqlalchemy/util/_concurrency_py3k.py", line 196, in greenlet_spawn
    value = await result
            ^^^^^^^^^^^^
  File "/home/runner/workspace/.pythonlibs/lib/python3.12/site-packages/aiosqlite/cursor.py", line 40, in execute
    await self._execute(self._cursor.execute, sql, parameters)
  File "/home/runner/workspace/.pythonlibs/lib/python3.12/site-packages/aiosqlite/cursor.py", line 32, in _execute
    return await self._conn._execute(fn, *args, **kwargs)
           ^^^^^^^^^^^^^^^^^^^^^^^^^^^^^^^^^^^^^^^^^^^^^^
  File "/home/runner/workspace/.pythonlibs/lib/python3.12/site-packages/aiosqlite/core.py", line 122, in _execute
    return await future
           ^^^^^^^^^^^^
  File "/home/runner/workspace/.pythonlibs/lib/python3.12/site-packages/aiosqlite/core.py", line 105, in run
    result = function()
             ^^^^^^^^^^
sqlite3.OperationalError: no such column: users.hashed_password

The above exception was the direct cause of the following exception:

Traceback (most recent call last):
  File "/home/runner/workspace/.pythonlibs/lib/python3.12/site-packages/uvicorn/protocols/http/h11_impl.py", line 408, in run_asgi
    result = await app(  # type: ignore[func-returns-value]
             ^^^^^^^^^^^^^^^^^^^^^^^^^^^^^^^^^^^^^^^^^^^^^^
  File "/home/runner/workspace/.pythonlibs/lib/python3.12/site-packages/uvicorn/middleware/proxy_headers.py", line 84, in __call__
    return await self.app(scope, receive, send)
           ^^^^^^^^^^^^^^^^^^^^^^^^^^^^^^^^^^^^
  File "/home/runner/workspace/.pythonlibs/lib/python3.12/site-packages/fastapi/applications.py", line 1054, in __call__
    await super().__call__(scope, receive, send)
  File "/home/runner/workspace/.pythonlibs/lib/python3.12/site-packages/starlette/applications.py", line 113, in __call__
    await self.middleware_stack(scope, receive, send)
  File "/home/runner/workspace/.pythonlibs/lib/python3.12/site-packages/starlette/middleware/errors.py", line 187, in __call__
    raise exc
  File "/home/runner/workspace/.pythonlibs/lib/python3.12/site-packages/starlette/middleware/errors.py", line 165, in __call__
    await self.app(scope, receive, _send)
  File "/home/runner/workspace/.pythonlibs/lib/python3.12/site-packages/starlette/middleware/exceptions.py", line 62, in __call__
    await wrap_app_handling_exceptions(self.app, conn)(scope, receive, send)
  File "/home/runner/workspace/.pythonlibs/lib/python3.12/site-packages/starlette/_exception_handler.py", line 62, in wrapped_app
    raise exc
  File "/home/runner/workspace/.pythonlibs/lib/python3.12/site-packages/starlette/_exception_handler.py", line 51, in wrapped_app
    await app(scope, receive, sender)
  File "/home/runner/workspace/.pythonlibs/lib/python3.12/site-packages/starlette/routing.py", line 715, in __call__
    await self.middleware_stack(scope, receive, send)
  File "/home/runner/workspace/.pythonlibs/lib/python3.12/site-packages/starlette/routing.py", line 735, in app
    await route.handle(scope, receive, send)
  File "/home/runner/workspace/.pythonlibs/lib/python3.12/site-packages/starlette/routing.py", line 288, in handle
    await self.app(scope, receive, send)
  File "/home/runner/workspace/.pythonlibs/lib/python3.12/site-packages/starlette/routing.py", line 76, in app
    await wrap_app_handling_exceptions(app, request)(scope, receive, send)
  File "/home/runner/workspace/.pythonlibs/lib/python3.12/site-packages/starlette/_exception_handler.py", line 62, in wrapped_app
    raise exc
  File "/home/runner/workspace/.pythonlibs/lib/python3.12/site-packages/starlette/_exception_handler.py", line 51, in wrapped_app
    await app(scope, receive, sender)
  File "/home/runner/workspace/.pythonlibs/lib/python3.12/site-packages/starlette/routing.py", line 73, in app
    response = await f(request)
               ^^^^^^^^^^^^^^^^
  File "/home/runner/workspace/.pythonlibs/lib/python3.12/site-packages/fastapi/routing.py", line 301, in app
    raw_response = await run_endpoint_function(
                   ^^^^^^^^^^^^^^^^^^^^^^^^^^^^
  File "/home/runner/workspace/.pythonlibs/lib/python3.12/site-packages/fastapi/routing.py", line 212, in run_endpoint_function
    return await dependant.call(**values)
           ^^^^^^^^^^^^^^^^^^^^^^^^^^^^^^
  File "/home/runner/workspace/app/api/v1/endpoints/users.py", line 32, in register
    db_user = await UserService.get_user_by_username(db, user.username)
              ^^^^^^^^^^^^^^^^^^^^^^^^^^^^^^^^^^^^^^^^^^^^^^^^^^^^^^^^^
  File "/home/runner/workspace/app/services/user.py", line 31, in get_user_by_username
    result = await db.execute(select(User).filter(User.username == username))
             ^^^^^^^^^^^^^^^^^^^^^^^^^^^^^^^^^^^^^^^^^^^^^^^^^^^^^^^^^^^^^^^^
  File "/home/runner/workspace/.pythonlibs/lib/python3.12/site-packages/sqlalchemy/ext/asyncio/session.py", line 463, in execute
    result = await greenlet_spawn(
             ^^^^^^^^^^^^^^^^^^^^^
  File "/home/runner/workspace/.pythonlibs/lib/python3.12/site-packages/sqlalchemy/util/_concurrency_py3k.py", line 201, in greenlet_spawn
    result = context.throw(*sys.exc_info())
             ^^^^^^^^^^^^^^^^^^^^^^^^^^^^^^
  File "/home/runner/workspace/.pythonlibs/lib/python3.12/site-packages/sqlalchemy/orm/session.py", line 2365, in execute
    return self._execute_internal(
           ^^^^^^^^^^^^^^^^^^^^^^^
  File "/home/runner/workspace/.pythonlibs/lib/python3.12/site-packages/sqlalchemy/orm/session.py", line 2251, in _execute_internal
    result: Result[Any] = compile_state_cls.orm_execute_statement(
                          ^^^^^^^^^^^^^^^^^^^^^^^^^^^^^^^^^^^^^^^^
  File "/home/runner/workspace/.pythonlibs/lib/python3.12/site-packages/sqlalchemy/orm/context.py", line 306, in orm_execute_statement
    result = conn.execute(
             ^^^^^^^^^^^^^
  File "/home/runner/workspace/.pythonlibs/lib/python3.12/site-packages/sqlalchemy/engine/base.py", line 1415, in execute
    return meth(
           ^^^^^
  File "/home/runner/workspace/.pythonlibs/lib/python3.12/site-packages/sqlalchemy/sql/elements.py", line 523, in _execute_on_connection
    return connection._execute_clauseelement(
           ^^^^^^^^^^^^^^^^^^^^^^^^^^^^^^^^^^
  File "/home/runner/workspace/.pythonlibs/lib/python3.12/site-packages/sqlalchemy/engine/base.py", line 1637, in _execute_clauseelement
    ret = self._execute_context(
          ^^^^^^^^^^^^^^^^^^^^^^
  File "/home/runner/workspace/.pythonlibs/lib/python3.12/site-packages/sqlalchemy/engine/base.py", line 1842, in _execute_context
    return self._exec_single_context(
           ^^^^^^^^^^^^^^^^^^^^^^^^^^
  File "/home/runner/workspace/.pythonlibs/lib/python3.12/site-packages/sqlalchemy/engine/base.py", line 1982, in _exec_single_context
    self._handle_dbapi_exception(
  File "/home/runner/workspace/.pythonlibs/lib/python3.12/site-packages/sqlalchemy/engine/base.py", line 2351, in _handle_dbapi_exception
    raise sqlalchemy_exception.with_traceback(exc_info[2]) from e
  File "/home/runner/workspace/.pythonlibs/lib/python3.12/site-packages/sqlalchemy/engine/base.py", line 1963, in _exec_single_context
    self.dialect.do_execute(
  File "/home/runner/workspace/.pythonlibs/lib/python3.12/site-packages/sqlalchemy/engine/default.py", line 943, in do_execute
    cursor.execute(statement, parameters)
  File "/home/runner/workspace/.pythonlibs/lib/python3.12/site-packages/sqlalchemy/dialects/sqlite/aiosqlite.py", line 149, in execute
    self._adapt_connection._handle_exception(error)
  File "/home/runner/workspace/.pythonlibs/lib/python3.12/site-packages/sqlalchemy/dialects/sqlite/aiosqlite.py", line 300, in _handle_exception
    raise error
  File "/home/runner/workspace/.pythonlibs/lib/python3.12/site-packages/sqlalchemy/dialects/sqlite/aiosqlite.py", line 131, in execute
    self.await_(_cursor.execute(operation, parameters))
  File "/home/runner/workspace/.pythonlibs/lib/python3.12/site-packages/sqlalchemy/util/_concurrency_py3k.py", line 132, in await_only
    return current.parent.switch(awaitable)  # type: ignore[no-any-return,attr-defined] # noqa: E501
           ^^^^^^^^^^^^^^^^^^^^^^^^^^^^^^^^
  File "/home/runner/workspace/.pythonlibs/lib/python3.12/site-packages/sqlalchemy/util/_concurrency_py3k.py", line 196, in greenlet_spawn
    value = await result
            ^^^^^^^^^^^^
  File "/home/runner/workspace/.pythonlibs/lib/python3.12/site-packages/aiosqlite/cursor.py", line 40, in execute
    await self._execute(self._cursor.execute, sql, parameters)
  File "/home/runner/workspace/.pythonlibs/lib/python3.12/site-packages/aiosqlite/cursor.py", line 32, in _execute
    return await self._conn._execute(fn, *args, **kwargs)
           ^^^^^^^^^^^^^^^^^^^^^^^^^^^^^^^^^^^^^^^^^^^^^^
  File "/home/runner/workspace/.pythonlibs/lib/python3.12/site-packages/aiosqlite/core.py", line 122, in _execute
    return await future
           ^^^^^^^^^^^^
  File "/home/runner/workspace/.pythonlibs/lib/python3.12/site-packages/aiosqlite/core.py", line 105, in run
    result = function()
             ^^^^^^^^^^
sqlalchemy.exc.OperationalError: (sqlite3.OperationalError) no such column: users.hashed_password
[SQL: SELECT users.id, users.username, users.email, users.hashed_password, users.created_at, users.updated_at 
FROM users 
WHERE users.username = ?]
[parameters: ('test_user',)]
(Background on this error at: https://sqlalche.me/e/20/e3q8)